<!-- 需求：设置机器人底盘，并添加一个摄像头 -->
<robot name="my_car"> 

    <!-- 添加一个尺寸极小的 link ，再去关联初始 link 与 base_link ,关节的高度刚好和 base_link 下沉的高度一致-->

    <link name="base_footprint">
        <visual>
            <geometry>
                <box size="0.001 0.001 0.001" />
            </geometry>
        </visual>
    </link>

    <!-- 关联 bse_footprint 与 base_link -->
    <joint name="link2basefootprint" type="fixed">
        <!-- 父级link -->
        <parent link="base_footprint"/>
        <!-- 子级link -->
        <child link="base_link"/>
        <!-- 设置偏移量 -->
        <origin xyz="0 0 0.05" rpy="0 0 0" />
    </joint>

    <!-- 1.底盘link -->
    <link name="base_link">
        <!-- 可视化标签 -->
        <visual>
            <!-- 1.形状 -->
            <geometry>
                <!-- 1.1 立方体 -->
                <box size="0.3 0.2 0.1" />
            </geometry>
            <origin xyz="0 0 0.0" rpy="0 0 0" />
            <material name="car_color">
                <color rgba="0.8 0.5 0 0.5" />
            </material>
        </visual>

    </link>
    <!-- 2.摄像头link -->
        <link name="camera">
        <!-- 可视化标签 -->
        <visual>
            <!-- 1.形状 -->
            <geometry>
                <!-- 1.1 立方体 -->
                <box size="0.02 0.05 0.05" />
            </geometry>
            <origin xyz="0 0 0.025" rpy="0 0 0" />

            <material name="camera_color">
                <color rgba="0 0 1 0.5" />
            </material>
        </visual>

    </link>
    <!-- 3.关节joint -->
    <joint name="camera2base" type="continuous">
        <!-- 父级link -->
        <parent link="base_link"/>
        <!-- 子级link -->
        <child link="camera"/>
        <!-- 设置偏移量 -->
        <origin xyz="0.12 0 0.05" rpy="0 0 0" />
        <!-- 设置关节旋转参考坐标轴 -->
        <axis xyz="0 0 1"/>
    </joint>

</robot>